Workbook

Sheet Intro
A1: Welcome!
A2: This spreadsheet is intended to help you do financial planning in a start-up.
A3: It should not be used as a "fill-in-the-blanks", but as a guide to understand the planning concepts.
A4: Start-ups and their planning varies a lot depending on the type. At times, I provide examples for different start-up types.
A5: This is not a best-practice approach, but illustrates possible approaches. Note: I simplfy often to make it easier to digest, but will highlight frequent mistakes.
A6: Also notice that this is just for the first year. Please make sure to plan at least for the first three years.
A7: If you find mistakes or have suggestions for improvement, please let me know: jan.brinckmann@gmail.com
A10: I use cell comments as additional information - just as in this cell.
A11: If you struggling with certain terms & concepts, research them on the internet.
A14: Structure:
A15: 1. I will start with the hiring plan to give us an idea of the size of operations and HR costs.
A16: 2. Next comes sales plan as the basis for projected revenues which is often the most tricky part.
... A26: © Jan Brinckmann

Sheet 1.Hiring Plan
A1: So how many people will work for our venture and what are their costs?
A3: Hiring Plan
A4: Staff required for development (Year 1 Barcelona only)
A6: Plan of incentives
G9: Month: | H9: 46388 | I9: 46419 | J9: 46447 | K9: 46478 | L9: 46508 | M9: 46539 | N9: 46569 | O9: 46600 | P9: 46631 | Q9: 46661 | R9: 46692 | S9: 46722 | T9: Total
A10: Founder | B10: Base Salary | C10: Benefits | D10: Total Expense | G10: # of founders | H10: 1 | I10: 1 | J10: 1 | K10: 1 | L10: 1 | M10: 1 | N10: 1 | O10: 1 | P10: 1 | Q10: 1 | R10: 1 | S10: 1
A11: Salary | B11: 1200 | C11: =B11*0.1 -> 120 | D11: =B11+C11 -> 1320 | G11: Founders Compensation | H11: =H10*$D$11 -> 1320 | I11: =I10*$D$11 -> 1320 | J11: =J10*$D$11 -> 1320 | K11: =K10*$D$11 -> 1320 | L11: =L10*$D$11 -> 1320 | M11: =M10*$D$11 -> 1320 | N11: =N10*$D$11 -> 1320 | O11: =O10*$D$11 -> 1320 | ... S11: =S10*$D$11 -> 1320 | T11: =SUM(H11:S11) -> 15840
A12: Freelance Developer | B12: MVP Dev. | C12: Maintenance | D12: Total Expense | G12: # of developers | H12: 1 | I12: 1 | J12: 1 | K12: 1 | L12: 1 | M12: 1 | N12: 1 | O12: 1 | P12: 1 | Q12: 1 | R12: 1 | S12: 1
A13: Salary | B13: =12000*1 -> 12000 | C13: =300*12 -> 3600 | D13: =B13+C13 -> 15600 | G13: Developers Compensation | H13: =(B13/2*H12) -> 6000 | I13: =(B13/2*I12) -> 6000 | J13: =(J12*$C$13)/12 -> 300 | K13: =(K12*$C$13)/12 -> 300 | L13: =(L12*$C$13)/12 -> 300 | M13: =(M12*$C$13)/12 -> 300 | N13: =(N12*$C$13)/12 -> 300 | O13: =(O12*$C$13)/12 -> 300 | P13: =(P12*$C$13)/12 -> 300 | Q13: =(Q12*$C$13)/12 -> 300 | ... S13: =(S12*$C$13)/12 -> 300 | T13: =SUM(H13:S13) -> 15000
G17: Total | H17: =$H$11+$H$13+$H$15 -> 7320 | I17: =$I$11+$I$13+$I$15 -> 7320 | J17: =$J$11+$J$13+$J$15 -> 1620 | K17: =$K$11+$K$13+$K$15 -> 1620 | L17: =$L$11+$L$13+$L$15 -> 1620 | M17: =$M$11+$M$13+$M$15 -> 1620 | N17: =$N$11+$N$13+$N$15 -> 1620 | O17: =$O$11+$O$13+$O$15 -> 1620 | P17: =$P$11+$P$13+$P$15 -> 1620 | Q17: =$Q$11+$Q$13+$Q$15 -> 1620 | R17: =$R$11+$R$13+$R$15 -> 1620 | S17: =$S$11+$S$13+$S$15 -> 1620 | T17: =T11+T13+T15 -> 30840

Sheet 2. SalesPlan
A1: So how much revenue can we generate? Here are different brief approaches to estimate sales
A3: Sales Plan | C3: Total Year 1 Revenue: | D3: =SUM(L24,K45,J70) -> 30721.284
A5: User Subscription Revenue Stream
A6: User Growth
A7: Starting Users = 50 | G7: Year 01 Month: | H7: 46388 | I7: 46419 | J7: 46447 | K7: 46478 | L7: 46508 | M7: 46539 | N7: 46569 | O7: 46600 | P7: 46631 | Q7: 46661 | R7: 46692 | S7: 46722 | U7: Total
G8: Users | H8: 50 | I8: =H8*(1+H9) -> 120 | J8: =I8*(1+I9) -> 249.6 | K8: =J8*(1+J9) -> 349.44 | L8: =K8*(1+K9) -> 499.6992 | M8: =L8*(1+L9) -> 699.57888 | N8: =M8*(1+M9) -> 902.45676 | O8: =N8*(1+N9) -> 1100.9972 | P8: =O8*(1+O9) -> 1299.1767 | ... S8: =R8*(1+R9) -> 1992.1706 | U8: =S8 -> 1992.1706
G9: Growth% | H9: 1.4 | I9: 1.08 | J9: 0.4 | K9: 0.43 | L9: 0.4 | M9: 0.29 | N9: 0.22 | O9: 0.18 | P9: 0.15 | Q9: 0.13 | R9: 0.18 | U9: =AVERAGE(H9:S9) -> 0.44181818
A12: Monetization Model | G12: Month | H12: Users | I12: Conversion Rate | J12: Paid Users | K12: Revenue | L12: Total
A13: Conversion Rates: | G13: January | H13: =H8 -> 50 | I13: =B14+(B15-B14) * (ROW() - ROW(I13)) / (B16 - 1) -> 0.1 | J13: =H8*I13 -> 5 | K13: =J13*B18 -> 39.95
A14: Start = | B14: 0.1 | G14: February | H14: =I8 -> 120 | I14: =B14+(B15-B14) * (ROW() - ROW(I13)) / (B16 - 1) -> 0.10727273 | J14: =I8*I14 -> 12.872727 | K14: =J14*B18 -> 102.85309
A15: End = | B15: 0.18 | G15: March | H15: =J8 -> 249.6 | I15: =B14+(B15-B14) * (2/11) -> 0.11454545 | J15: =J8*I15 -> 28.590545 | K15: =J15*B18 -> 228.43846
A16: Months = | B16: 12 | G16: April | H16: =K8 -> 349.44 | I16: =B14+(B15-B14) * (3/11) -> 0.12181818 | J16: =K8*I16 -> 42.568145 | K16: =J16*B18 -> 340.11948
G17: May | H17: =L8 -> 499.6992 | I17: =B14+(B15-B14) * (4/11) -> 0.12909091 | J17: =L8*I17 -> 64.506624 | K17: =J17*B18 -> 515.40793
A18: Price = | B18: 7.99 | G18: June | H18: =M8 -> 699.57888 | I18: =B14+(B15-B14) * (5/11) -> 0.13636364 | J18: =M8*I18 -> 95.39712 | K18: =J18*B18 -> 762.22299
G19: July | H19: =N8 -> 902.45676 | I19: =B14+(B15-B14) * (6/11) -> 0.14363636 | J19: =N8*I19 -> 129.62561 | K19: =J19*B18 -> 1035.7086
G20: August | H20: =O8 -> 1100.9972 | I20: =B14+(B15-B14) * (7/11) -> 0.15090909 | J20: =O8*I20 -> 166.15049 | K20: =J20*B18 -> 1327.5424
G21: September | H21: =P8 -> 1299.1767 | I21: =B14+(B15-B14) * (8/11) -> 0.15818182 | J21: =P8*I21 -> 205.50614 | K21: =J21*B18 -> 1641.9941
G22: October | H22: =Q8 -> 1494.0533 | I22: =B14+(B15-B14) * (9/11) -> 0.16545455 | J22: =Q8*I22 -> 247.1979 | K22: =J22*B18 -> 1975.1112
G23: November | H23: =R8 -> 1688.2802 | I23: =B14+(B15-B14) * (10/11) -> 0.17272727 | J23: =R8*I23 -> 291.61203 | K23: =J23*B18 -> 2329.9801
G24: December | H24: =S8 -> 1992.1706 | I24: =B14+(B15-B14) * (11/11) -> 0.18 | J24: =S8*I24 -> 358.59071 | K24: =J24*B18 -> 2865.1398 | L24: =SUM(K13:K24) -> 13164.468
A30: Courses
A31: Engaged Users = | B31: 0.5
A32: Conversion = | B32: 0.1
A33: Price Avg. | B33: 25 | G33: Month: | H33: Users | I33: Buyers | J33: Revenue | K33: Total
G34: January | H34: =H13 -> 50 | I34: =H34*B31*B32 -> 2.5 | J34: =B33*I34 -> 62.5
G35: February | H35: =H14 -> 120 | I35: =H35*B31*B32 -> 6 | J35: =B33*I35 -> 150
G36: March | H36: =H15 -> 249.6 | I36: =H36*B31*B32 -> 12.48 | J36: =B33*I36 -> 312
G37: April | H37: =H16 -> 349.44 | I37: =H37*B31*B32 -> 17.472 | J37: =B33*I37 -> 436.8
G38: May | H38: =H17 -> 499.6992 | I38: =H38*B31*B32 -> 24.98496 | J38: =B33*I38 -> 624.624
G39: June | H39: =H18 -> 699.57888 | I39: =H39*B31*B32 -> 34.978944 | J39: =B33*I39 -> 874.4736
G40: July | H40: =H19 -> 902.45676 | I40: =H40*B31*B32 -> 45.122838 | J40: =B33*I40 -> 1128.0709
G41: August | H41: =H20 -> 1100.9972 | I41: =H41*B31*B32 -> 55.049862 | J41: =B33*I41 -> 1376.2466
G42: September | H42: =H21 -> 1299.1767 | I42: =H42*B31*B32 -> 64.958837 | J42: =B33*I42 -> 1623.9709
G43: October | H43: =H22 -> 1494.0533 | I43: =H43*B31*B32 -> 74.702663 | J43: =B33*I43 -> 1867.5666
G44: November | H44: =H23 -> 1688.2802 | I44: =H44*B31*B32 -> 84.414009 | J44: =B33*I44 -> 2110.3502
G45: December | H45: =H24 -> 1992.1706 | I45: =H45*B31*B32 -> 99.608531 | J45: =B33*I45 -> 2490.2133 | K45: =SUM(J34:J45) -> 13056.816
A55: B2B (Venues)
A56: Starting Venues = | B56: 2
A57: Growth per Month = | B57: 1
A58: Price per Venue/m = | B58: 50 | G58: Month: | H58: Venues | I58: Revenue | J58: Total
...

Sheet 3. Profit & Loss (Income)
A1: So will we be turning a profit?
E3: Month: | F3: 46388 | G3: 46419 | H3: 46447 | I3: 46478 | J3: 46508 | K3: 46539 | L3: 46569 | M3: 46600 | N3: 46631 | O3: 46661 | P3: 46692 | Q3: 46722 | R3: Total
B4: REVENUES
B5: Subscriptions | F5: ='2. SalesPlan'!K13 -> 39.95 | G5: ='2. SalesPlan'!K14 -> 102.85309 | H5: ='2. SalesPlan'!K15 -> 228.43846 | I5: ='2. SalesPlan'!K16 -> 340.11948 | J5: ='2. SalesPlan'!K17 -> 515.40793 | K5: ='2. SalesPlan'!K18 -> 762.22299 | L5: ='2. SalesPlan'!K19 -> 1035.7086 | M5: ='2. SalesPlan'!K20 -> 1327.5424 | N5: ='2. SalesPlan'!K21 -> 1641.9941 | O5: ='2. SalesPlan'!K22 -> 1975.1112 | P5: ='2. SalesPlan'!K23 -> 2329.9801 | Q5: ='2. SalesPlan'!K24 -> 2865.1398 | R5: =SUM(F5:Q5) -> 13164.468
B6: Courses | F6: ='2. SalesPlan'!J34 -> 62.5 | G6: ='2. SalesPlan'!J35 -> 150 | H6: ='2. SalesPlan'!J36 -> 312 | I6: ='2. SalesPlan'!J37 -> 436.8 | J6: ='2. SalesPlan'!J38 -> 624.624 | K6: ='2. SalesPlan'!J39 -> 874.4736 | L6: ='2. SalesPlan'!J40 -> 1128.0709 | M6: ='2. SalesPlan'!J41 -> 1376.2466 | N6: ='2. SalesPlan'!J42 -> 1623.9709 | O6: ='2. SalesPlan'!J43 -> 1867.5666 | P6: ='2. SalesPlan'!J44 -> 2110.3502 | Q6: ='2. SalesPlan'!J45 -> 2490.2133 | R6: =SUM(F6:Q6) -> 13056.816
B7: B2B Venue Fees | F7: ='2. SalesPlan'!I59 -> 100 | G7: ='2. SalesPlan'!I60 -> 150 | H7: ='2. SalesPlan'!I61 -> 200 | I7: ='2. SalesPlan'!I62 -> 250 | J7: ='2. SalesPlan'!I63 -> 300 | K7: ='2. SalesPlan'!I64 -> 350 | L7: ='2. SalesPlan'!I65 -> 400 | M7: ='2. SalesPlan'!I66 -> 450 | N7: ='2. SalesPlan'!I67 -> 500 | O7: ='2. SalesPlan'!I68 -> 550 | P7: ='2. SalesPlan'!I69 -> 600 | Q7: ='2. SalesPlan'!I70 -> 650 | R7: =SUM(F7:Q7) -> 4500
B8: TOTAL REVENUES | F8: =SUM(F5:F7) -> 202.45 | G8: =SUM(G5:G7) -> 402.85309 | H8: =SUM(H5:H7) -> 740.43846 | I8: =SUM(I5:I7) -> 1026.9195 | J8: =SUM(J5:J7) -> 1440.0319 | K8: =SUM(K5:K7) -> 1986.6966 | L8: =SUM(L5:L7) -> 2563.7795 | M8: =SUM(M5:M7) -> 3153.789 | ... R8: =SUM(R5:R7) -> 30721.284
B10: COGS
B11: Infrastructure (Firebase/AWS) | F11: 0 | G11: 0 | H11: 100 | I11: 100 | J11: 100 | K11: 100 | L11: 100 | M11: 100 | N11: 100 | O11: 100 | P11: 100 | Q11: 100 | R11: =SUM(F11:Q11) -> 1000
B12: Payment Processing | F12: =0.025*F5 -> 0.99875 | G12: =0.025*G5 -> 2.5713273 | H12: =0.025*H5 -> 5.7109615 | I12: =0.025*I5 -> 8.5029871 | J12: =0.025*J5 -> 12.885198 | K12: =0.025*K5 -> 19.055575 | L12: =0.025*L5 -> 25.892715 | M12: =0.025*M5 -> 33.188561 | ... Q12: =0.025*Q5 -> 71.628494 | R12: =SUM(F12:Q12) -> 329.1117
B13: TOTAL COGS | F13: =SUM(F11,F12) -> 0.99875 | G13: =SUM(G11,G12) -> 2.5713273 | H13: =SUM(H11,H12) -> 105.71096 | I13: =SUM(I11,I12) -> 108.50299 | J13: =SUM(J11,J12) -> 112.8852 | K13: =SUM(K11,K12) -> 119.05557 | L13: =SUM(L11,L12) -> 125.89271 | M13: =SUM(M11,M12) -> 133.18856 | ... Q13: =SUM(Q11,Q12) -> 171.62849 | R13: =SUM(R11:R12) -> 1329.1117
B14: GROSS PROFIT | R14: =R8-R13 -> 29392.173
B15: GROSS MARGIN | R15: =R14/R8 -> 0.95673645
B16: FIXED OPEX
B17: Founder Salary | F17: ='1.Hiring Plan'!H11 -> 1320 | G17: ='1.Hiring Plan'!I11 -> 1320 | H17: ='1.Hiring Plan'!J11 -> 1320 | I17: ='1.Hiring Plan'!K11 -> 1320 | J17: ='1.Hiring Plan'!L11 -> 1320 | K17: ='1.Hiring Plan'!M11 -> 1320 | L17: ='1.Hiring Plan'!N11 -> 1320 | M17: ='1.Hiring Plan'!O11 -> 1320 | ... R17: ='1.Hiring Plan'!T11 -> 15840
B18: Ammortization (MVP) | F18: 333 | G18: 333 | H18: 333 | I18: 333 | J18: 333 | K18: 333 | L18: 333 | M18: 333 | N18: 333 | O18: 335 | P18: 334 | Q18: 334 | R18: =SUM(F18:Q18) -> 4000
B19: Developer (Maintenance) | F19: 0 | G19: 0 | H19: ='1.Hiring Plan'!J13 -> 300 | I19: ='1.Hiring Plan'!K13 -> 300 | J19: ='1.Hiring Plan'!L13 -> 300 | K19: ='1.Hiring Plan'!M13 -> 300 | L19: ='1.Hiring Plan'!N13 -> 300 | M19: ='1.Hiring Plan'!O13 -> 300 | N19: ='1.Hiring Plan'!P13 -> 300 | O19: ='1.Hiring Plan'!Q13 -> 300 | ... Q19: ='1.Hiring Plan'!S13 -> 300 | R19: =SUM(F19:Q19) -> 3000
B20: Legal/Setup | F20: 750 | G20: 0 | H20: 0 | I20: 0 | J20: 0 | K20: 0 | L20: 0 | M20: 0 | N20: 0 | O20: 0 | P20: 0 | Q20: 0 | R20: =SUM(F20:Q20) -> 750
B21: TOTAL FIXED OPEX | F21: =SUM(F17:F19) -> 1653 | G21: =SUM(G17:G19) -> 1653 | H21: =SUM(H17:H19) -> 1953 | I21: =SUM(I17:I19) -> 1953 | J21: =SUM(J17:J19) -> 1953 | K21: =SUM(K17:K19) -> 1953 | L21: =SUM(L17:L19) -> 1953 | M21: =SUM(M17:M19) -> 1953 | ... Q21: =SUM(Q17:Q19) -> 1954 | R21: =SUM(R17:R20) -> 23590
B22: VARIABLE OPEX
B23: Marketing | F23: 0 | G23: 0 | H23: 250 | I23: 250 | J23: 500 | K23: 500 | L23: 500 | M23: 500 | N23: 500 | O23: 500 | P23: 500 | Q23: 500 | R23: =SUM(F23:Q23) -> 4500
B24: TOTAL VARIABLE OPEX | F24: =SUM(F23) -> 0 | G24: =SUM(G23) -> 0 | H24: =SUM(H23) -> 250 | I24: =SUM(I23) -> 250 | J24: =SUM(J23) -> 500 | K24: =SUM(K23) -> 500 | L24: =SUM(L23) -> 500 | M24: =SUM(M23) -> 500 | ... R24: =SUM(R23) -> 4500
B25: TOTAL COSTS | R25: =SUM(R13,R21,R24) -> 29419.112
B27: NET PROFIT/LOSS | F27: =F8-F13-F21-F23 -> -1451.5487 | G27: =G8-G13-G21-G23 -> -1252.7182 | H27: =H8-H13-H21-H23 -> -1568.2725 | I27: =I8-I13-I21-I23 -> -1284.5835 | J27: =J8-J13-J21-J23 -> -1125.8533 | K27: =K8-K13-K21-K23 -> -585.35899 | L27: =L8-L13-L21-L23 -> -15.113174 | M27: =M8-M13-M21-M23 -> 567.60043 | ... Q27: =Q8-Q13-Q21-Q23 -> 3379.7245
B28: CUMULATIVE P&L | R28: =SUM(R8,-R25) -> 1302.1726

Sheet 4. Cash-flow statement
A1: There are two fundamental approaches to build the cash-flow statement (direct method and the indirect method)
A2: The indirect method is used here. The direct method is more straight forward: You start with the opening balance, list all cash that you collected in the time and the expenses you incurred. This leads you to the ending balance.
B4: Opening Balance | D4: ='3. Profit & Loss (Income)'!E3 -> Month: | E4: ='3. Profit & Loss (Income)'!F3 -> 46388 | F4: ='3. Profit & Loss (Income)'!G3 -> 46419 | G4: ='3. Profit & Loss (Income)'!H3 -> 46447 | H4: ='3. Profit & Loss (Income)'!I3 -> 46478 | I4: ='3. Profit & Loss (Income)'!J3 -> 46508 | J4: ='3. Profit & Loss (Income)'!K3 -> 46539 | K4: ='3. Profit & Loss (Income)'!L3 -> 46569 | ... P4: ='3. Profit & Loss (Income)'!Q3 -> 46722 | Q4: Total
B5: Initial Funding (equity) | E5: 15000 | F5: 0 | G5: 0 | H5: 0 | I5: 0 | J5: 0 | K5: 0 | L5: 0 | M5: 0 | N5: 0 | O5: 0 | P5: 0
B6: Opening Cash Balance | E6: 0 | F6: =E28 -> 8451.4513 | G6: =F28 -> 2851.733 | H6: =G28 -> 2936.4605 | I6: =H28 -> 3304.877 | J6: =I28 -> 3832.0237 | K6: =J28 -> 4899.6647 | L6: =K28 -> 6537.5516 | M6: =L28 -> 8758.152 | ... Q6: =P28 -> 24142.173 | R6: Year Closing
B8: Cash Inflows
B9: Subscription Revenue | E9: ='3. Profit & Loss (Income)'!F5 -> 39.95 | F9: ='3. Profit & Loss (Income)'!G5 -> 102.85309 | G9: ='3. Profit & Loss (Income)'!H5 -> 228.43846 | H9: ='3. Profit & Loss (Income)'!I5 -> 340.11948 | I9: ='3. Profit & Loss (Income)'!J5 -> 515.40793 | J9: ='3. Profit & Loss (Income)'!K5 -> 762.22299 | K9: ='3. Profit & Loss (Income)'!L5 -> 1035.7086 | L9: ='3. Profit & Loss (Income)'!M5 -> 1327.5424 | ... Q9: ='3. Profit & Loss (Income)'!R5 -> 13164.468
B10: Course Revenue | E10: ='3. Profit & Loss (Income)'!F6 -> 62.5 | F10: ='3. Profit & Loss (Income)'!G6 -> 150 | G10: ='3. Profit & Loss (Income)'!H6 -> 312 | H10: ='3. Profit & Loss (Income)'!I6 -> 436.8 | I10: ='3. Profit & Loss (Income)'!J6 -> 624.624 | J10: ='3. Profit & Loss (Income)'!K6 -> 874.4736 | K10: ='3. Profit & Loss (Income)'!L6 -> 1128.0709 | L10: ='3. Profit & Loss (Income)'!M6 -> 1376.2466 | ... Q10: ='3. Profit & Loss (Income)'!R6 -> 13056.816
B11: B2B Venue Fee Revenue | E11: ='3. Profit & Loss (Income)'!F7 -> 100 | F11: ='3. Profit & Loss (Income)'!G7 -> 150 | G11: ='3. Profit & Loss (Income)'!H7 -> 200 | H11: ='3. Profit & Loss (Income)'!I7 -> 250 | I11: ='3. Profit & Loss (Income)'!J7 -> 300 | J11: ='3. Profit & Loss (Income)'!K7 -> 350 | K11: ='3. Profit & Loss (Income)'!L7 -> 400 | L11: ='3. Profit & Loss (Income)'!M7 -> 450 | ... Q11: ='3. Profit & Loss (Income)'!R7 -> 4500
B12: Total Inflows | E12: =SUM(E9:E11) -> 202.45 | F12: =SUM(F9:F11) -> 402.85309 | G12: =SUM(G9:G11) -> 740.43846 | H12: =SUM(H9:H11) -> 1026.9195 | I12: =SUM(I9:I11) -> 1440.0319 | J12: =SUM(J9:J11) -> 1986.6966 | K12: =SUM(K9:K11) -> 2563.7795 | L12: =SUM(L9:L11) -> 3153.789 | ... Q12: =SUM(Q9:Q11) -> 30721.284
B14: Cash Outflows
B15: Founder Salary (Deferred) | E15: 0 | F15: 0 | G15: 0 | H15: 0 | I15: 0 | J15: 0 | K15: 0 | L15: 0 | M15: 0 | N15: 0 | O15: 0 | P15: 0 | Q15: 0
B16: Developer (Maintenance) | E16: ='3. Profit & Loss (Income)'!F19 -> 0 | F16: ='3. Profit & Loss (Income)'!G19 -> 0 | G16: ='3. Profit & Loss (Income)'!H19 -> 300 | H16: ='3. Profit & Loss (Income)'!I19 -> 300 | I16: ='3. Profit & Loss (Income)'!J19 -> 300 | J16: ='3. Profit & Loss (Income)'!K19 -> 300 | K16: ='3. Profit & Loss (Income)'!L19 -> 300 | L16: ='3. Profit & Loss (Income)'!M19 -> 300 | ... Q16: ='3. Profit & Loss (Income)'!R19 -> 3000
B17: Legal/Setup | E17: ='3. Profit & Loss (Income)'!F20 -> 750 | F17: ='3. Profit & Loss (Income)'!G20 -> 0 | G17: ='3. Profit & Loss (Income)'!H20 -> 0 | H17: ='3. Profit & Loss (Income)'!I20 -> 0 | I17: ='3. Profit & Loss (Income)'!J20 -> 0 | J17: ='3. Profit & Loss (Income)'!K20 -> 0 | K17: ='3. Profit & Loss (Income)'!L20 -> 0 | L17: ='3. Profit & Loss (Income)'!M20 -> 0 | ... Q17: ='3. Profit & Loss (Income)'!R20 -> 750
B18: Infrastructure (Firebase/AWS) | E18: ='3. Profit & Loss (Income)'!F11 -> 0 | F18: ='3. Profit & Loss (Income)'!G11 -> 0 | G18: ='3. Profit & Loss (Income)'!H11 -> 100 | H18: ='3. Profit & Loss (Income)'!I11 -> 100 | I18: ='3. Profit & Loss (Income)'!J11 -> 100 | J18: ='3. Profit & Loss (Income)'!K11 -> 100 | K18: ='3. Profit & Loss (Income)'!L11 -> 100 | L18: ='3. Profit & Loss (Income)'!M11 -> 100 | ... Q18: ='3. Profit & Loss (Income)'!R11 -> 1000
B19: Payment Processing | E19: ='3. Profit & Loss (Income)'!F12 -> 0.99875 | F19: ='3. Profit & Loss (Income)'!G12 -> 2.5713273 | G19: ='3. Profit & Loss (Income)'!H12 -> 5.7109615 | H19: ='3. Profit & Loss (Income)'!I12 -> 8.5029871 | I19: ='3. Profit & Loss (Income)'!J12 -> 12.885198 | J19: ='3. Profit & Loss (Income)'!K12 -> 19.055575 | K19: ='3. Profit & Loss (Income)'!L12 -> 25.892715 | L19: ='3. Profit & Loss (Income)'!M12 -> 33.188561 | ... Q19: ='3. Profit & Loss (Income)'!R12 -> 329.1117
B20: Marketing | E20: ='3. Profit & Loss (Income)'!F23 -> 0 | F20: ='3. Profit & Loss (Income)'!G23 -> 0 | G20: ='3. Profit & Loss (Income)'!H23 -> 250 | H20: ='3. Profit & Loss (Income)'!I23 -> 250 | I20: ='3. Profit & Loss (Income)'!J23 -> 500 | J20: ='3. Profit & Loss (Income)'!K23 -> 500 | K20: ='3. Profit & Loss (Income)'!L23 -> 500 | L20: ='3. Profit & Loss (Income)'!M23 -> 500 | ... Q20: ='3. Profit & Loss (Income)'!R23 -> 4500
B21: Total Outflows | E21: =SUM(E15:E20) -> 750.99875 | F21: =SUM(F15:F20) -> 2.5713273 | G21: =SUM(G15:G20) -> 655.71096 | H21: =SUM(H15:H20) -> 658.50299 | I21: =SUM(I15:I20) -> 912.8852 | J21: =SUM(J15:J20) -> 919.05557 | K21: =SUM(K15:K20) -> 925.89271 | L21: =SUM(L15:L20) -> 933.18856 | ... Q21: =SUM(Q15:Q20) -> 9579.1117
B23: CAPEX
B24: MVP Capitalization | E24: -6000 | F24: -6000 | G24: 0 | H24: 0 | I24: 0 | J24: 0 | K24: 0 | L24: 0 | M24: 0 | N24: 0 | O24: 0 | P24: 0 | Q24: =SUM(E24:P24) -> -12000
B26: Net Cash Flow
B27: Net Cash Flow | E27: =E12-E21+E24 -> -6548.5487 | F27: =F12-F21+F24 -> -5599.7182 | G27: =G12-G21+G24 -> 84.727497 | H27: =H12-H21+H24 -> 368.4165 | I27: =I12-I21+I24 -> 527.14673 | J27: =J12-J21+J24 -> 1067.641 | K27: =K12-K21+K24 -> 1637.8868 | L27: =L12-L21+L24 -> 2220.6004 | ... P27: =P12-P21+P24 -> 5033.7245 | Q27: =SUM(E27:P27) -> 9142.1726
B28: Closing Balance | E28: =E5+E6+E27 -> 8451.4513 | F28: =F5+F6+F27 -> 2851.733 | G28: =G5+G6+G27 -> 2936.4605 | H28: =H5+H6+H27 -> 3304.877 | I28: =I5+I6+I27 -> 3832.0237 | J28: =J5+J6+J27 -> 4899.6647 | K28: =K5+K6+K27 -> 6537.5516 | L28: =L5+L6+L27 -> 8758.152 | ... P28: =P5+P6+P27 -> 24142.173 | Q28: =P28 -> 24142.173
B30: *Deferred Founder Salary * to be paid to founder when profitable | E30: 1320 | F30: =E30*2 -> 2640 | G30: =E30*3 -> 3960 | H30: =E30*4 -> 5280 | I30: =E30*5 -> 6600 | J30: =E30*6 -> 7920 | K30: =E30*7 -> 9240 | L30: =E30*8 -> 10560 | M30: =E30*9 -> 11880 | N30: =E30*10 -> 13200 | O30: =E30*11 -> 14520 | P30: =E30*12 -> 15840 | Q30: =P30 -> 15840

Sheet 5. Balance Sheet
A1: The Balance Sheet (by years)
A2: Note that this is an aggregation of numers you have calculated before if you have already aggregated the monthly figures to create yearly figures.
A3: Hence, please refernce to the respective parts.
F4: End of Year One | G4: End of Year Two
A6: Assets
B7: Current Assets
C8: Cash | F8: ='4. Cash-flow statement'!Q28 -> 24142.173
B13: Total Current Assets | F13: =SUM(F8:F12) -> 24142.173 | G13: =SUM(G8:G12) -> 0
B15: Fixed Assets
F16: ='[1]10. Balance Sheet'!I13 -> 0 | G16: =F16 -> 0
C17: MVP Development | F17: 12000
G18: =F18 -> 0
G19: =F19 -> 0
G20: =F20 -> 0
G21: =F21 -> 0
G22: =F22+'[1]13. Cash Flow Statement (2)'!Q12 -> 0
B23: Total Fixed Assets | F23: =SUM(F16:F22) -> 12000 | G23: =SUM(G16:G22) -> 0
B25: Accumulated Depreciation | F25: 4000
A27: Total Assets | F27: =INT(F13+F23-F25) -> 32142 | G27: =INT(G13+G23-G25) -> 0
A31: Liabilities and Owner's Equity
B32: Liabilities
C33: Deferred Salary | F33: ='3. Profit & Loss (Income)'!R17 -> 15840
G34: ='[1]20. Amoritization Schedule'!R16+'[1]7. Beginning Balance Sheet'!F31 -> 0
G35: ='[1]20. Amoritization Schedule'!R36+'[1]7. Beginning Balance Sheet'!F32 -> 0
G36: ='[1]20. Amoritization Schedule'!R56+'[1]7. Beginning Balance Sheet'!F33 -> 0
G37: ='[1]20. Amoritization Schedule'!R76+'[1]7. Beginning Balance Sheet'!F34 -> 0
G38: ='[1]20. Amoritization Schedule'!R96+'[1]7. Beginning Balance Sheet'!F35 -> 0
G39: ='[1]13. Cash Flow Statement (2)'!P35+'[1]7. Beginning Balance Sheet'!F33 -> 0
B40: Total Liabilities | F40: =SUM(F33:F39) -> 15840 | G40: =SUM(G33:G39) -> 0
B42: Owner's Equity
C43: Common Stock | F43: ='4. Cash-flow statement'!E5 -> 15000
C44: Retained Earnings | F44: ='3. Profit & Loss (Income)'!R28 -> 1302.1726
F45: ='[1]10. Balance Sheet'!I42 -> 0
B46: Total Owner's Equity | F46: =F43+F44-F45 -> 16302.173
A48: Total Liabilities and Owner's Equity | F48: =INT(F40+F46) -> 32142

Sheet 6. CAC & CLV
A1: Often the calculations for the whole venture distract from understanding the per customer economics.
A2: This sheet is intended to depict some sample calculation which are often done, before developing the financials of the venture.
A3: These calculations can inform the development of the financials of the business plan.
A6: Example: Venture based on mailing list marketing campaign
A8: CAC (Customer Acquisition Costs): | B8: Y1
A10: Total Users Acquired Y1 | B10: ='2. SalesPlan'!S8 -> 1992.1706
A11: Organic (60%) | B11: =B10*0.6 -> 1195.3024
A12: Marketing Driven (40%) | B12: =B10*0.4 -> 796.86824
A14: Total Marketing Spend | B14: ='3. Profit & Loss (Income)'!R23 -> 4500
A15: CAC (paid users only) | B15: =B14/B12 -> 5.6471067
A16: Blended CAC (all users) | B16: =B14/B10 -> 2.2588427
A19: CLV (Customer Lifetime Value)
A21: Average Subscription Duration (months) | B21: 12
A22: Monthly Subscription Rate (18% of users by Dec) | B22: ='2. SalesPlan'!B18 -> 7.99
A23: Subscription revenue/user | B23: =B22*B21 -> 95.88
A25: Courses (per total user base) | B25: ='2. SalesPlan'!B33*0.05 -> 1.25
A26: B2B Venue Fee | B26: ='2. SalesPlan'!J70/B10 -> 2.2588427
A28: Blended LTV/user
A29: Subscription Contribution (blended across all users) | B29: =B23*0.18 -> 17.2584
A30: Course Contribution | B30: =B25 -> 1.25
A31: Venue Fee Contribution | B31: =B26 -> 2.2588427
A32: Total Blended LTV | B32: =SUM(B29:B31) -> 20.767243
A34: LTV/CAC x (Blended) | B34: =B32/B16 -> 9.1937535

Sheet 7. Sensitivity Analysis
A1: In the sensitivity analysis is most likely the most insightful part of the work. The idea to change key assumption of the plan and see how other key variables change
A3: KEY VARIABLES
A5: Conversion Rate (free ---- paid)
A6: User growth (total users)
A7: Marketing spend
A10: Conversion Rate (base 10-18%)
B11: Scenario | C11: Conversion Rate | D11: Sub Revenue | E11: Net Profit
B12: Pessimistic -50% | C12: 5-9% | D12: =D13*0.5 -> 6582.2341 | E12: =E13-D13*0.5 -> -5280.0615
B13: Base Case 0% | C13: 10-18% | D13: ='2. SalesPlan'!L24 -> 13164.468 | E13: ='3. Profit & Loss (Income)'!R28 -> 1302.1726
B14: Optimistic +25% | C14: 12-22% | D14: =D13*0.25+D13 -> 16455.585 | E14: =D13*0.25+E13 -> 4593.2896
B15: Optimistic +50% | C15: 15-27 | D15: =D13*0.5+D13 -> 19746.702 | E15: =D13*0.5+E13 -> 7884.4067
A17: User Growth
B18: Scenario | C18: Total Users | D18: Total Revenue | E18: Net Profit
B19: Pessimistic -50% | C19: =C20*0.5 -> 996.08531 | D19: =D20*0.5 -> 15360.642 | E19: =D20*0.5-'3. Profit & Loss (Income)'!R25 -> -14058.47
B20: Base Case 0% | C20: ='2. SalesPlan'!S8 -> 1992.1706 | D20: ='3. Profit & Loss (Income)'!R8 -> 30721.284 | E20: ='3. Profit & Loss (Income)'!R28 -> 1302.1726
B21: Optimistic +25% | C21: =C20*0.25+C20 -> 2490.2133 | D21: =D20*0.25+D20 -> 38401.605 | E21: =D21-'3. Profit & Loss (Income)'!R25 -> 8982.4936
B22: Optimistic +50% | C22: =C20*0.5+C20 -> 2988.2559 | D22: =D20*0.5+D20 -> 46081.926 | E22: =D22-'3. Profit & Loss (Income)'!R25 -> 16662.815
A24: Marketing Spend
B25: Scenario | C25: Mkt Spend | D25: Net Profit
B26: No Marketing | C26: 0 | D26: =D27+C27 -> 5802.1726
B27: Base Case | C27: ='3. Profit & Loss (Income)'!R23 -> 4500 | D27: =E20 -> 1302.1726
B28: Double | C28: =C27*2 -> 9000 | D28: =D27-C27 -> -3197.8274
B29: Triple | C29: =C27*3 -> 13500 | D29: =D27-C28 -> -7697.8274

Sheet 8. KPIs
A1: Please Identify the key KPIs here and show how other indicators that drive the respective KPIs
A3: Top KPIs: | D3: KPI_1: Monthly Active Users (MAU) | F3: KPI_2: Paid Conversion Rate | I3: KPI_3: Revenue per User
A5: Sub-KPIs: | D5: KPI_1.1: New Users/month | Churn Rate | F5: KPI_2.1 Free to paid conversions |Paying Users Total | I5: KPI_3.1: Subscription ARPU €7.99 | Blended ARPU €2.26
A9: Evolution of KPIs:
C10: Month | D10: MAU | E10: Conversion % | F10: Paying Users | G10: Monthly Revenue | H10: ARPU
C11: Jan | D11: ='2. SalesPlan'!H13 -> 50 | E11: ='2. SalesPlan'!I13 -> 0.1 | F11: ='2. SalesPlan'!J13 -> 5 | G11: ='3. Profit & Loss (Income)'!F8 -> 202.45 | H11: =G11/D11 -> 4.049
C12: Mar | D12: ='2. SalesPlan'!H15 -> 249.6 | E12: ='2. SalesPlan'!I15 -> 0.11454545 | F12: ='2. SalesPlan'!J15 -> 28.590545 | G12: ='3. Profit & Loss (Income)'!H8 -> 740.43846 | H12: =G12/D12 -> 2.9665002
C13: Jun | D13: ='2. SalesPlan'!H18 -> 699.57888 | E13: ='2. SalesPlan'!I18 -> 0.13636364 | F13: ='2. SalesPlan'!J18 -> 95.39712 | G13: ='3. Profit & Loss (Income)'!K8 -> 1986.6966 | H13: =G13/D13 -> 2.8398464
C14: Sep | D14: ='2. SalesPlan'!H21 -> 1299.1767 | E14: ='2. SalesPlan'!I21 -> 0.15818182 | F14: ='2. SalesPlan'!J21 -> 205.50614 | G14: ='3. Profit & Loss (Income)'!N8 -> 3765.965 | H14: =G14/D14 -> 2.8987318
C15: Dec | D15: ='2. SalesPlan'!H24 -> 1992.1706 | E15: ='2. SalesPlan'!I24 -> 0.18 | F15: ='2. SalesPlan'!J24 -> 358.59071 | G15: ='3. Profit & Loss (Income)'!Q8 -> 6005.353 | H15: =G15/D15 -> 3.0144773

Sheet 9. Cap Tables
A1: DEC 2027 | G1: JAN 2028
C3: Share in company in percent
A4: Sweat Equity & 15k cash contribution | B4: ='4. Cash-flow statement'!E5 -> 15000 | C4: =B4/$B$6 -> 0.92012276 | G4: Pre-money
A5: Retained Earnings | B5: ='3. Profit & Loss (Income)'!R28 -> 1302.1726 | C5: =B5/$B$6 -> 0.079877241 | G5: Invested Money
A6: Total value of firm | B6: =SUM(B4:B5) -> 16302.173 | C6: =SUM(C4:C5) -> 1 | G6: Post-money
